<mujoco model="ant">
  <compiler angle="degree" coordinate="local" inertiafromgeom="true"/>
  <option integrator="RK4" timestep="0.01"/>
  <custom>
    <numeric data="0.0 0.0 0.55 1.0 0.0 0.0 0.0 0.0 1.0 0.0 -1.0 0.0 -1.0 0.0 1.0" name="init_qpos"/>
  </custom>
  <default>
    <joint armature="1" damping="1" limited="true"/>
    <geom conaffinity="0" condim="3" density="5.0" friction="1 0.5 0.5" margin="0.01" rgba="0.8 0.6 0.4 1"/>
  </default>
  <asset>
    <texture builtin="gradient" height="100" rgb1="1 1 1" rgb2="0 0 0" type="skybox" width="100"/>
    <texture builtin="flat" height="1278" mark="cross" markrgb="1 1 1" name="texgeom" random="0.01" rgb1="0.8 0.6 0.4" rgb2="0.8 0.6 0.4" type="cube" width="127"/>
    <texture builtin="checker" height="100" name="texplane" rgb1="0 0 0" rgb2="0.8 0.8 0.8" type="2d" width="100"/>
    <material name="MatPlane" reflectance="0.5" shininess="1" specular="1" texrepeat="60 60" texture="texplane"/>
    <material name="geom" texture="texgeom" texuniform="true"/>
  </asset>
  <worldbody>
    <light cutoff="100" diffuse="1 1 1" dir="-0 0 -1.3" directional="true" exponent="1" pos="0 0 1.3" specular=".1 .1 .1"/>
    <geom conaffinity="1" condim="3" material="MatPlane" name="floor" pos="0 0 0" rgba="0.8 0.9 0.8 1" size="40 40 40" type="plane"/>
    <body name="torso" pos="0 0 0.4">
      <camera name="track" mode="trackcom" pos="0 -3 0.3" xyaxes="1 0 0 0 0 1"/>
      <geom name="torso_geom" pos="0 0 0" size="0.2 0.1" type="cylinder"/>
      <joint armature="0" damping="0" limited="false" margin="0.01" name="root" pos="0 0 0" type="free"/>
      <site name="sensor_site0" pos="0 0 0" size="0.06" type="sphere" rgba=".9 .9 .1 1"/>
      <body name="front_left_leg" pos="0 0 0">
        <geom fromto="0.0 0.0 -0.04 0.2 0.2 -0.04" name="aux_1_geom" size="0.05" type="capsule"/>
        <body name="aux_1" pos="0.2 0.2 0">
          <joint axis="0 0 1" name="hip_1" pos="0.0 0.0 -0.04" range="-45 45" type="hinge"/>
          <geom fromto="0.0 0.0 -0.04 0.06 0.06 -0.04" name="left_leg_geom" size="0.05" type="capsule"/>
          <site name="sensor_site1" pos="0.03 0.03 0" size="0.02" type="sphere" rgba=".9 .9 .1 1"/>
          <body pos="0.06 0.06 0">
            <joint axis="1 -1 0" name="ankle_1" pos="0.0 0.0 -0.04" range="-80 -30" type="hinge"/>
            <geom fromto="0.0 0.0 -0.04 0.1 0.1 -0.04" name="left_ankle_geom" size="0.05" type="capsule"/>
            <site name="sensor_site2" pos="0.05 0.05 0" size="0.02" type="sphere" rgba=".9 .9 .1 1"/>
            <geom fromto="0.1 0.1 -0.04 0.13 0.13 -0.065" name="left_foot_geom" size="0.05" type="capsule"/>
            <site name="fl_foot" pos="0.13 0.13 -0.065" size="0.06" type="sphere" rgba=".9 .9 .1 1"/>
          </body>
        </body>
      </body>
      <body name="front_right_leg" pos="0 0 0">
        <geom fromto="0.0 0.0 -0.04 0.2 -0.2 -0.04" name="aux_2_geom" size="0.05" type="capsule"/>
        <body name="aux_2" pos="0.2 -0.2 0">
          <joint axis="0 0 1" name="hip_2" pos="0.0 0.0 -0.04" range="-45 45" type="hinge"/>
          <geom fromto="0.0 0.0 -0.04 0.06 -0.06 -0.04" name="right_leg_geom" size="0.05" type="capsule"/>
          <site name="sensor_site3" pos="0.03 -0.03 0" size="0.02" type="sphere" rgba=".9 .9 .1 1"/>
          <body pos="0.06 -0.06 0">
            <joint axis="1 1 0" name="ankle_2" pos="0.0 0.0 -0.04" range="30 80" type="hinge"/>
            <geom fromto="0.0 0.0 -0.04 0.1 -0.1 -0.04" name="right_ankle_geom" size="0.05" type="capsule"/>
            <site name="sensor_site4" pos="0.05 -0.05 0" size="0.02" type="sphere" rgba=".9 .9 .1 1"/>
            <geom fromto="0.1 -0.1 -0.04 0.13 -0.13 -0.065" name="right_foot_geom" size="0.05" type="capsule"/>
            <site name="fr_foot" pos="0.13 -0.13 -0.065" size="0.06" type="sphere" rgba=".9 .9 .1 1"/>
          </body>
        </body>
      </body>
      <body name="back_left_leg" pos="0 0 0">
        <geom fromto="0.0 0.0 -0.04 -0.2 0.2 -0.04" name="aux_3_geom" size="0.05" type="capsule"/>
        <body name="aux_3" pos="-0.2 0.2 0">
          <joint axis="0 0 1" name="hip_3" pos="0.0 0.0 -0.04" range="-45 45" type="hinge"/>
          <geom fromto="0.0 0.0 -0.04 -0.06 0.06 -0.04" name="back_left_leg_geom" size="0.05" type="capsule"/>
          <site name="sensor_site5" pos="-0.03 0.03 0" size="0.02" type="sphere" rgba=".9 .9 .1 1"/>
          <body pos="-0.06 0.06 0">
            <joint axis="1 1 0" name="ankle_3" pos="0.0 0.0 -0.04" range="-80 -30" type="hinge"/>
            <geom fromto="0.0 0.0 -0.04 -0.1 0.1 -0.04" name="third_ankle_geom" size="0.05" type="capsule"/>
            <site name="sensor_site6" pos="-0.05 0.05 0" size="0.02" type="sphere" rgba=".9 .9 .1 1"/>
            <geom fromto="-0.1 0.1 -0.04 -0.13 0.13 -0.065" name="third_foot_geom" size="0.05" type="capsule"/>
            <site name="bl_foot" pos="-0.13 0.13 -0.065" size="0.06" type="sphere" rgba=".9 .9 .1 1"/>
          </body>
        </body>
      </body>
      <body name="back_right_leg" pos="0 0 0">
        <geom fromto="0.0 0.0 -0.04 -0.2 -0.2 -0.04" name="aux_4_geom" size="0.05" type="capsule"/>
        <body name="aux_4" pos="-0.2 -0.2 0">
          <joint axis="0 0 1" name="hip_4" pos="0.0 0.0 -0.04" range="-45 45" type="hinge"/>
          <geom fromto="0.0 0.0 -0.04 -0.06 -0.06 -0.04" name="back_right_leg_geom" size="0.05" type="capsule"/>
          <site name="sensor_site7" pos="-0.03 -0.03 0" size="0.02" type="sphere" rgba=".9 .9 .1 1"/>
          <body pos="-0.06 -0.06 0">
            <joint axis="1 -1 0" name="ankle_4" pos="0.0 0.0 -0.04" range="30 80" type="hinge"/>
            <geom fromto="0.0 0.0 -0.04 -0.1 -0.1 -0.04" name="fourth_ankle_geom" size="0.05" type="capsule"/>
            <site name="sensor_site8" pos="-0.05 -0.05 0" size="0.02" type="sphere" rgba=".9 .9 .1 1"/>
            <geom fromto="-0.1 -0.1 -0.04 -0.13 -0.13 -0.065" name="fourth_foot_geom" size="0.05" type="capsule"/>
            <site name="br_foot" pos="-0.13 -0.13 -0.065" size="0.06" type="sphere" rgba=".9 .9 .1 1"/>
          </body>
        </body>
      </body>
    </body>
  </worldbody>
  <actuator>
    <motor name="servo_1" ctrllimited="true" ctrlrange="-1.0 1.0" joint="hip_1" gear="50"/>
    <motor name="servo_2" ctrllimited="true" ctrlrange="-1.0 1.0" joint="ankle_1" gear="50"/>
    <motor name="servo_3" ctrllimited="true" ctrlrange="-1.0 1.0" joint="hip_2" gear="50"/>
    <motor name="servo_4" ctrllimited="true" ctrlrange="-1.0 1.0" joint="ankle_2" gear="50"/>
    <motor name="servo_5" ctrllimited="true" ctrlrange="-1.0 1.0" joint="hip_3" gear="50"/>
    <motor name="servo_6" ctrllimited="true" ctrlrange="-1.0 1.0" joint="ankle_3" gear="50"/>
    <motor name="servo_7" ctrllimited="true" ctrlrange="-1.0 1.0" joint="hip_4" gear="50"/>
    <motor name="servo_8" ctrllimited="true" ctrlrange="-1.0 1.0" joint="ankle_4" gear="50"/>
  </actuator>
  <sensor>
    <framepos name="pos" objtype="body" objname="torso" noise="0.05"/>
    <framequat name="quat" objtype="body" objname="torso" noise="0.05"/>

    <accelerometer name="lin_acc" site="sensor_site0" noise="0.05"/>
    <accelerometer name="fl_hip_lin_acc" site="sensor_site1" noise="0.05"/>
    <accelerometer name="fl_ankle_lin_acc" site="sensor_site2" noise="0.05"/>
    <accelerometer name="fr_hip_lin_acc" site="sensor_site3" noise="0.05"/>
    <accelerometer name="fr_ankle_lin_acc" site="sensor_site4" noise="0.05"/>
    <accelerometer name="bl_hip_lin_acc" site="sensor_site5" noise="0.05"/>
    <accelerometer name="bl_ankle_lin_acc" site="sensor_site6" noise="0.05"/>
    <accelerometer name="br_hip_lin_acc" site="sensor_site7" noise="0.05"/>
    <accelerometer name="br_ankle_lin_acc" site="sensor_site8" noise="0.05"/>

    <gyro name="ang_vel" site="sensor_site0" noise="0.05"/>
    <gyro name="fl_hip_ang_vel" site="sensor_site1" noise="0.05"/>    
    <gyro name="fl_ankle_ang_vel" site="sensor_site2" noise="0.05"/> 
    <gyro name="fr_hip_ang_vel" site="sensor_site3" noise="0.05"/>  
    <gyro name="fr_ankle_ang_vel" site="sensor_site4" noise="0.05"/>  
    <gyro name="bl_hip_ang_vel" site="sensor_site5" noise="0.05"/>  
    <gyro name="bl_ankle_ang_vel" site="sensor_site6" noise="0.05"/>  
    <gyro name="br_hip_ang_vel" site="sensor_site7" noise="0.05"/> 
    <gyro name="br_ankle_ang_vel" site="sensor_site8" noise="0.05"/>

    <actuatorfrc name="frc_1" actuator="servo_1" noise="0.05"/>
    <actuatorfrc name="frc_2" actuator="servo_2" noise="0.05"/>
    <actuatorfrc name="frc_3" actuator="servo_3" noise="0.05"/>
    <actuatorfrc name="frc_4" actuator="servo_4" noise="0.05"/>
    <actuatorfrc name="frc_5" actuator="servo_5" noise="0.05"/>
    <actuatorfrc name="frc_6" actuator="servo_6" noise="0.05"/>
    <actuatorfrc name="frc_7" actuator="servo_7" noise="0.05"/>
    <actuatorfrc name="frc_8" actuator="servo_8" noise="0.05"/> 

    <jointvel name="vel_1" joint="hip_1" noise="0.05"/>
    <jointvel name="vel_2" joint="ankle_1" noise="0.05"/>  
    <jointvel name="vel_3" joint="hip_2" noise="0.05"/> 
    <jointvel name="vel_4" joint="ankle_2" noise="0.05"/> 
    <jointvel name="vel_5" joint="hip_3" noise="0.05"/>
    <jointvel name="vel_6" joint="ankle_3" noise="0.05"/>
    <jointvel name="vel_7" joint="hip_4" noise="0.05"/>
    <jointvel name="vel_8" joint="ankle_4" noise="0.05"/>

    <jointpos name="pos_1" joint="hip_1" noise="0.05"/>
    <jointpos name="pos_2" joint="ankle_1" noise="0.05"/>  
    <jointpos name="pos_3" joint="hip_2" noise="0.05"/> 
    <jointpos name="pos_4" joint="ankle_2" noise="0.05"/> 
    <jointpos name="pos_5" joint="hip_3" noise="0.05"/>
    <jointpos name="pos_6" joint="ankle_3" noise="0.05"/>
    <jointpos name="pos_7" joint="hip_4" noise="0.05"/>
    <jointpos name="pos_8" joint="ankle_4" noise="0.05"/>

    <touch name="touch_1" site="fl_foot" noise="0.05"/>
    <touch name="touch_2" site="fr_foot" noise="0.05"/>
    <touch name="touch_3" site="bl_foot" noise="0.05"/>
    <touch name="touch_4" site="br_foot" noise="0.05"/>

  </sensor>
</mujoco>
